Workbook

Sheet 2027 밸류에이션
A2: 반도체·전자부품 90종목 2027년 밸류에이션
A3: 주가: 2026-10-15 KRX 정규장 종가(KST). 금액: 억원, 주가: 원, 배수: 배.
A4: 기존표 27E 추정치 유지 (기존 83종목 10/10, 추가 7종목 10/14). 26E 추정치는 FnGuide 10/14 컨센서스. YoY = 기존표 27E ÷ FnGuide 26E - 1.
A5: PER = 보통주 시가총액 / 27E 순이익. POR = 보통주 시가총액 / 27E 영업이익. 시총 = 10/15 종가 × 상장주식 수.
A6: † 원표의 연결순이익·지배순이익 차이 5% 초과 표시 유지. 기존 순이익의 회계기준은 원표 기준으로 통일하지 않음.
A7: 마이크로컨텍솔·테크윙·제우스: 2027년 컨센서스 공란으로 PER·POR 미산출. 임의 추정 미적용.
A8: 시가총액 방식은 EPS 방식과 다를 수 있음. YoY의 26E/27E 출처 기준이 다르며, 27E 교차점검 차이는 원자료 X열. 26E 적자·0은 백분율 대신 흑자전환·적자지속 등으로 표기. | J8: 10/14 기준
A9: 순위 | B9: 종목 | C9: 코드 | D9: 10/15 종가 | E9: 시가총액 | F9: 26E 순이익 | G9: 27E 순이익 | H9: 27E 순이익 YoY | I9: 26E 영업이익 | J9: 27E 영업이익 | K9: 27E 영업이익 YoY | L9: 27E PER | M9: 27E POR | N9: 27E ROE | O9: 원표 PER | P9: 원표 POR | Q9: 구분 / 순이익 기준
A10: 55 | B10: 세미파이브 | C10: 490470 | D10: =원자료!I67 | E10: =D10*원자료!J67/100000000 | F10: =IF(원자료!T67="","미확인",원자료!T67) | G10: =IF(원자료!D67="","미확인",원자료!D67) | H10: =IF(AND(ISNUMBER(F10),ISNUMBER(G10)),IF(F10=0,IF(G10>0,"흑자전환",IF(G10=0,"손익분기","미확인")),IF(F10<0,IF(G10>0,"흑자전환",IF(G10=0,"손익분기","적자지속")),IF(G10<0,"적자전환",IF(G10=0,-1,G10/F10-1)))),"미확인") | I10: =IF(원자료!U67="","미확인",원자료!U67) | J10: =IF(원자료!E67="","미확인",원자료!E67) | K10: =IF(AND(ISNUMBER(I10),ISNUMBER(J10)),IF(I10=0,IF(J10>0,"흑자전환",IF(J10=0,"손익분기","미확인")),IF(I10<0,IF(J10>0,"흑자전환",IF(J10=0,"손익분기","적자지속")),IF(J10<0,"적자전환",IF(J10=0,-1,J10/I10-1)))),"미확인") | L10: =IF(ISNUMBER(G10),IF(G10>0,E10/G10,"적자"),"미산출") | M10: =IF(ISNUMBER(J10),IF(J10>0,E10/J10,"적자"),"미산출") | N10: =IF(원자료!O67="","미확인",원자료!O67) | O10: 20.4 | P10: 19.2 | Q10: 기존 / 원표 기준
A11: 76 | B11: SFA반도체 | C11: 036540 | D11: =원자료!I83 | E11: =D11*원자료!J83/100000000 | F11: =IF(원자료!T83="","미확인",원자료!T83) | G11: =IF(원자료!D83="","미확인",원자료!D83) | H11: =IF(AND(ISNUMBER(F11),ISNUMBER(G11)),IF(F11=0,IF(G11>0,"흑자전환",IF(G11=0,"손익분기","미확인")),IF(F11<0,IF(G11>0,"흑자전환",IF(G11=0,"손익분기","적자지속")),IF(G11<0,"적자전환",IF(G11=0,-1,G11/F11-1)))),"미확인") | I11: =IF(원자료!U83="","미확인",원자료!U83) | J11: =IF(원자료!E83="","미확인",원자료!E83) | K11: =IF(AND(ISNUMBER(I11),ISNUMBER(J11)),IF(I11=0,IF(J11>0,"흑자전환",IF(J11=0,"손익분기","미확인")),IF(I11<0,IF(J11>0,"흑자전환",IF(J11=0,"손익분기","적자지속")),IF(J11<0,"적자전환",IF(J11=0,-1,J11/I11-1)))),"미확인") | L11: =IF(ISNUMBER(G11),IF(G11>0,E11/G11,"적자"),"미산출") | M11: =IF(ISNUMBER(J11),IF(J11>0,E11/J11,"적자"),"미산출") | N11: =IF(원자료!O83="","미확인",원자료!O83) | O11: 28.2 | P11: 22.4 | Q11: 기존 / 원표 기준
A12: 86 | B12: 한미반도체 | C12: 042700 | D12: =원자료!I91 | E12: =D12*원자료!J91/100000000 | F12: =IF(원자료!T91="","미확인",원자료!T91) | G12: =IF(원자료!D91="","미확인",원자료!D91) | H12: =IF(AND(ISNUMBER(F12),ISNUMBER(G12)),IF(F12=0,IF(G12>0,"흑자전환",IF(G12=0,"손익분기","미확인")),IF(F12<0,IF(G12>0,"흑자전환",IF(G12=0,"손익분기","적자지속")),IF(G12<0,"적자전환",IF(G12=0,-1,G12/F12-1)))),"미확인") | I12: =IF(원자료!U91="","미확인",원자료!U91) | J12: =IF(원자료!E91="","미확인",원자료!E91) | K12: =IF(AND(ISNUMBER(I12),ISNUMBER(J12)),IF(I12=0,IF(J12>0,"흑자전환",IF(J12=0,"손익분기","미확인")),IF(I12<0,IF(J12>0,"흑자전환",IF(J12=0,"손익분기","적자지속")),IF(J12<0,"적자전환",IF(J12=0,-1,J12/I12-1)))),"미확인") | L12: =IF(ISNUMBER(G12),IF(G12>0,E12/G12,"적자"),"미산출") | M12: =IF(ISNUMBER(J12),IF(J12>0,E12/J12,"적자"),"미산출") | N12: =IF(원자료!O91="","미확인",원자료!O91) | O12: 46.2 | P12: 42.2 | Q12: 기존 / 원표 기준
A13: 88 | B13: 마이크로컨텍솔 | C13: 098120 | D13: =원자료!I93 | E13: =D13*원자료!J93/100000000 | F13: =IF(원자료!T93="","미확인",원자료!T93) | G13: =IF(원자료!D93="","미확인",원자료!D93) | H13: =IF(AND(ISNUMBER(F13),ISNUMBER(G13)),IF(F13=0,IF(G13>0,"흑자전환",IF(G13=0,"손익분기","미확인")),IF(F13<0,IF(G13>0,"흑자전환",IF(G13=0,"손익분기","적자지속")),IF(G13<0,"적자전환",IF(G13=0,-1,G13/F13-1)))),"미확인") | I13: =IF(원자료!U93="","미확인",원자료!U93) | J13: =IF(원자료!E93="","미확인",원자료!E93) | K13: =IF(AND(ISNUMBER(I13),ISNUMBER(J13)),IF(I13=0,IF(J13>0,"흑자전환",IF(J13=0,"손익분기","미확인")),IF(I13<0,IF(J13>0,"흑자전환",IF(J13=0,"손익분기","적자지속")),IF(J13<0,"적자전환",IF(J13=0,-1,J13/I13-1)))),"미확인") | L13: =IF(ISNUMBER(G13),IF(G13>0,E13/G13,"적자"),"미산출") | M13: =IF(ISNUMBER(J13),IF(J13>0,E13/J13,"적자"),"미산출") | N13: =IF(원자료!O93="","미확인",원자료!O93) | Q13: 추가 / 컨센서스 없음
A14: 89 | B14: 테크윙 | C14: 089030 | D14: =원자료!I98 | E14: =D14*원자료!J98/100000000 | F14: =IF(원자료!T98="","미확인",원자료!T98) | G14: =IF(원자료!D98="","미확인",원자료!D98) | H14: =IF(AND(ISNUMBER(F14),ISNUMBER(G14)),IF(F14=0,IF(G14>0,"흑자전환",IF(G14=0,"손익분기","미확인")),IF(F14<0,IF(G14>0,"흑자전환",IF(G14=0,"손익분기","적자지속")),IF(G14<0,"적자전환",IF(G14=0,-1,G14/F14-1)))),"미확인") | I14: =IF(원자료!U98="","미확인",원자료!U98) | J14: =IF(원자료!E98="","미확인",원자료!E98) | K14: =IF(AND(ISNUMBER(I14),ISNUMBER(J14)),IF(I14=0,IF(J14>0,"흑자전환",IF(J14=0,"손익분기","미확인")),IF(I14<0,IF(J14>0,"흑자전환",IF(J14=0,"손익분기","적자지속")),IF(J14<0,"적자전환",IF(J14=0,-1,J14/I14-1)))),"미확인") | L14: =IF(ISNUMBER(G14),IF(G14>0,E14/G14,"적자"),"미산출") | M14: =IF(ISNUMBER(J14),IF(J14>0,E14/J14,"적자"),"미산출") | N14: =IF(원자료!O98="","미확인",원자료!O98) | Q14: 추가 / 컨센서스 없음
A15: 90 | B15: 제우스 | C15: 079370 | D15: =원자료!I99 | E15: =D15*원자료!J99/100000000 | F15: =IF(원자료!T99="","미확인",원자료!T99) | G15: =IF(원자료!D99="","미확인",원자료!D99) | H15: =IF(AND(ISNUMBER(F15),ISNUMBER(G15)),IF(F15=0,IF(G15>0,"흑자전환",IF(G15=0,"손익분기","미확인")),IF(F15<0,IF(G15>0,"흑자전환",IF(G15=0,"손익분기","적자지속")),IF(G15<0,"적자전환",IF(G15=0,-1,G15/F15-1)))),"미확인") | I15: =IF(원자료!U99="","미확인",원자료!U99) | J15: =IF(원자료!E99="","미확인",원자료!E99) | K15: =IF(AND(ISNUMBER(I15),ISNUMBER(J15)),IF(I15=0,IF(J15>0,"흑자전환",IF(J15=0,"손익분기","미확인")),IF(I15<0,IF(J15>0,"흑자전환",IF(J15=0,"손익분기","적자지속")),IF(J15<0,"적자전환",IF(J15=0,-1,J15/I15-1)))),"미확인") | L15: =IF(ISNUMBER(G15),IF(G15>0,E15/G15,"적자"),"미산출") | M15: =IF(ISNUMBER(J15),IF(J15>0,E15/J15,"적자"),"미산출") | N15: =IF(원자료!O99="","미확인",원자료!O99) | Q15: 추가 / 컨센서스 없음
A16: 62 | B16: 사피엔반도체 | C16: 452430 | D16: =원자료!I65 | E16: =D16*원자료!J65/100000000 | F16: =IF(원자료!T65="","미확인",원자료!T65) | G16: =IF(원자료!D65="","미확인",원자료!D65) | H16: =IF(AND(ISNUMBER(F16),ISNUMBER(G16)),IF(F16=0,IF(G16>0,"흑자전환",IF(G16=0,"손익분기","미확인")),IF(F16<0,IF(G16>0,"흑자전환",IF(G16=0,"손익분기","적자지속")),IF(G16<0,"적자전환",IF(G16=0,-1,G16/F16-1)))),"미확인") | I16: =IF(원자료!U65="","미확인",원자료!U65) | J16: =IF(원자료!E65="","미확인",원자료!E65) | K16: =IF(AND(ISNUMBER(I16),ISNUMBER(J16)),IF(I16=0,IF(J16>0,"흑자전환",IF(J16=0,"손익분기","미확인")),IF(I16<0,IF(J16>0,"흑자전환",IF(J16=0,"손익분기","적자지속")),IF(J16<0,"적자전환",IF(J16=0,-1,J16/I16-1)))),"미확인") | L16: =IF(ISNUMBER(G16),IF(G16>0,E16/G16,"적자"),"미산출") | M16: =IF(ISNUMBER(J16),IF(J16>0,E16/J16,"적자"),"미산출") | N16: =IF(원자료!O65="","미확인",원자료!O65) | O16: 20.1 | P16: 20.1 | Q16: 기존 / 원표 기준
A17: 53 | B17: 인텍플러스 | C17: 064290 | D17: =원자료!I56 | E17: =D17*원자료!J56/100000000 | F17: =IF(원자료!T56="","미확인",원자료!T56) | G17: =IF(원자료!D56="","미확인",원자료!D56) | H17: =IF(AND(ISNUMBER(F17),ISNUMBER(G17)),IF(F17=0,IF(G17>0,"흑자전환",IF(G17=0,"손익분기","미확인")),IF(F17<0,IF(G17>0,"흑자전환",IF(G17=0,"손익분기","적자지속")),IF(G17<0,"적자전환",IF(G17=0,-1,G17/F17-1)))),"미확인") | I17: =IF(원자료!U56="","미확인",원자료!U56) | J17: =IF(원자료!E56="","미확인",원자료!E56) | K17: =IF(AND(ISNUMBER(I17),ISNUMBER(J17)),IF(I17=0,IF(J17>0,"흑자전환",IF(J17=0,"손익분기","미확인")),IF(I17<0,IF(J17>0,"흑자전환",IF(J17=0,"손익분기","적자지속")),IF(J17<0,"적자전환",IF(J17=0,-1,J17/I17-1)))),"미확인") | L17: =IF(ISNUMBER(G17),IF(G17>0,E17/G17,"적자"),"미산출") | M17: =IF(ISNUMBER(J17),IF(J17>0,E17/J17,"적자"),"미산출") | N17: =IF(원자료!O56="","미확인",원자료!O56) | O17: 16.5 | P17: 13.7 | Q17: 기존 / 원표 기준
A18: 25 | B18: 피엠티 | C18: 147760 | D18: =원자료!I37 | E18: =D18*원자료!J37/100000000 | F18: =IF(원자료!T37="","미확인",원자료!T37) | G18: =IF(원자료!D37="","미확인",원자료!D37) | H18: =IF(AND(ISNUMBER(F18),ISNUMBER(G18)),IF(F18=0,IF(G18>0,"흑자전환",IF(G18=0,"손익분기","미확인")),IF(F18<0,IF(G18>0,"흑자전환",IF(G18=0,"손익분기","적자지속")),IF(G18<0,"적자전환",IF(G18=0,-1,G18/F18-1)))),"미확인") | I18: =IF(원자료!U37="","미확인",원자료!U37) | J18: =IF(원자료!E37="","미확인",원자료!E37) | K18: =IF(AND(ISNUMBER(I18),ISNUMBER(J18)),IF(I18=0,IF(J18>0,"흑자전환",IF(J18=0,"손익분기","미확인")),IF(I18<0,IF(J18>0,"흑자전환",IF(J18=0,"손익분기","적자지속")),IF(J18<0,"적자전환",IF(J18=0,-1,J18/I18-1)))),"미확인") | L18: =IF(ISNUMBER(G18),IF(G18>0,E18/G18,"적자"),"미산출") | M18: =IF(ISNUMBER(J18),IF(J18>0,E18/J18,"적자"),"미산출") | N18: =IF(원자료!O37="","미확인",원자료!O37) | O18: 12.3 | P18: 11 | Q18: 기존 / 원표 기준
A19: 12 | B19: 텔레칩스 | C19: 054450 | D19: =원자료!I21 | E19: =D19*원자료!J21/100000000 | F19: =IF(원자료!T21="","미확인",원자료!T21) | G19: =IF(원자료!D21="","미확인",원자료!D21) | H19: =IF(AND(ISNUMBER(F19),ISNUMBER(G19)),IF(F19=0,IF(G19>0,"흑자전환",IF(G19=0,"손익분기","미확인")),IF(F19<0,IF(G19>0,"흑자전환",IF(G19=0,"손익분기","적자지속")),IF(G19<0,"적자전환",IF(G19=0,-1,G19/F19-1)))),"미확인") | I19: =IF(원자료!U21="","미확인",원자료!U21) | J19: =IF(원자료!E21="","미확인",원자료!E21) | K19: =IF(AND(ISNUMBER(I19),ISNUMBER(J19)),IF(I19=0,IF(J19>0,"흑자전환",IF(J19=0,"손익분기","미확인")),IF(I19<0,IF(J19>0,"흑자전환",IF(J19=0,"손익분기","적자지속")),IF(J19<0,"적자전환",IF(J19=0,-1,J19/I19-1)))),"미확인") | L19: =IF(ISNUMBER(G19),IF(G19>0,E19/G19,"적자"),"미산출") | M19: =IF(ISNUMBER(J19),IF(J19>0,E19/J19,"적자"),"미산출") | N19: =IF(원자료!O21="","미확인",원자료!O21) | O19: 8.1 | P19: 6.6 | Q19: 기존 / 원표 기준
A20: 37 | B20: 에이디테크놀로지 | C20: 200710 | D20: =원자료!I49 | E20: =D20*원자료!J49/100000000 | F20: =IF(원자료!T49="","미확인",원자료!T49) | G20: =IF(원자료!D49="","미확인",원자료!D49) | H20: =IF(AND(ISNUMBER(F20),ISNUMBER(G20)),IF(F20=0,IF(G20>0,"흑자전환",IF(G20=0,"손익분기","미확인")),IF(F20<0,IF(G20>0,"흑자전환",IF(G20=0,"손익분기","적자지속")),IF(G20<0,"적자전환",IF(G20=0,-1,G20/F20-1)))),"미확인") | I20: =IF(원자료!U49="","미확인",원자료!U49) | J20: =IF(원자료!E49="","미확인",원자료!E49) | K20: =IF(AND(ISNUMBER(I20),ISNUMBER(J20)),IF(I20=0,IF(J20>0,"흑자전환",IF(J20=0,"손익분기","미확인")),IF(I20<0,IF(J20>0,"흑자전환",IF(J20=0,"손익분기","적자지속")),IF(J20<0,"적자전환",IF(J20=0,-1,J20/I20-1)))),"미확인") | L20: =IF(ISNUMBER(G20),IF(G20>0,E20/G20,"적자"),"미산출") | M20: =IF(ISNUMBER(J20),IF(J20>0,E20/J20,"적자"),"미산출") | N20: =IF(원자료!O49="","미확인",원자료!O49) | O20: 14 | P20: 11.4 | Q20: 기존 / 원표 기준
A21: 28 | B21: 에이엘티 | C21: 172670 | D21: =원자료!I34 | E21: =D21*원자료!J34/100000000 | F21: =IF(원자료!T34="","미확인",원자료!T34) | G21: =IF(원자료!D34="","미확인",원자료!D34) | H21: =IF(AND(ISNUMBER(F21),ISNUMBER(G21)),IF(F21=0,IF(G21>0,"흑자전환",IF(G21=0,"손익분기","미확인")),IF(F21<0,IF(G21>0,"흑자전환",IF(G21=0,"손익분기","적자지속")),IF(G21<0,"적자전환",IF(G21=0,-1,G21/F21-1)))),"미확인") | I21: =IF(원자료!U34="","미확인",원자료!U34) | J21: =IF(원자료!E34="","미확인",원자료!E34) | K21: =IF(AND(ISNUMBER(I21),ISNUMBER(J21)),IF(I21=0,IF(J21>0,"흑자전환",IF(J21=0,"손익분기","미확인")),IF(I21<0,IF(J21>0,"흑자전환",IF(J21=0,"손익분기","적자지속")),IF(J21<0,"적자전환",IF(J21=0,-1,J21/I21-1)))),"미확인") | L21: =IF(ISNUMBER(G21),IF(G21>0,E21/G21,"적자"),"미산출") | M21: =IF(ISNUMBER(J21),IF(J21>0,E21/J21,"적자"),"미산출") | N21: =IF(원자료!O34="","미확인",원자료!O34) | O21: 10.9 | P21: 8.8 | Q21: 기존 / 원표 기준
A22: 52 | B22: 파두 | C22: 440110 | D22: =원자료!I62 | E22: =D22*원자료!J62/100000000 | F22: =IF(원자료!T62="","미확인",원자료!T62) | G22: =IF(원자료!D62="","미확인",원자료!D62) | H22: =IF(AND(ISNUMBER(F22),ISNUMBER(G22)),IF(F22=0,IF(G22>0,"흑자전환",IF(G22=0,"손익분기","미확인")),IF(F22<0,IF(G22>0,"흑자전환",IF(G22=0,"손익분기","적자지속")),IF(G22<0,"적자전환",IF(G22=0,-1,G22/F22-1)))),"미확인") | I22: =IF(원자료!U62="","미확인",원자료!U62) | J22: =IF(원자료!E62="","미확인",원자료!E62) | K22: =IF(AND(ISNUMBER(I22),ISNUMBER(J22)),IF(I22=0,IF(J22>0,"흑자전환",IF(J22=0,"손익분기","미확인")),IF(I22<0,IF(J22>0,"흑자전환",IF(J22=0,"손익분기","적자지속")),IF(J22<0,"적자전환",IF(J22=0,-1,J22/I22-1)))),"미확인") | L22: =IF(ISNUMBER(G22),IF(G22>0,E22/G22,"적자"),"미산출") | M22: =IF(ISNUMBER(J22),IF(J22>0,E22/J22,"적자"),"미산출") | N22: =IF(원자료!O62="","미확인",원자료!O62) | O22: 19 | P22: 17 | Q22: 기존 / 원표 기준
A23: 47 | B23: 넥스틴 | C23: 348210 | D23: =원자료!I57 | E23: =D23*원자료!J57/100000000 | F23: =IF(원자료!T57="","미확인",원자료!T57) | G23: =IF(원자료!D57="","미확인",원자료!D57) | H23: =IF(AND(ISNUMBER(F23),ISNUMBER(G23)),IF(F23=0,IF(G23>0,"흑자전환",IF(G23=0,"손익분기","미확인")),IF(F23<0,IF(G23>0,"흑자전환",IF(G23=0,"손익분기","적자지속")),IF(G23<0,"적자전환",IF(G23=0,-1,G23/F23-1)))),"미확인") | I23: =IF(원자료!U57="","미확인",원자료!U57) | J23: =IF(원자료!E57="","미확인",원자료!E57) | K23: =IF(AND(ISNUMBER(I23),ISNUMBER(J23)),IF(I23=0,IF(J23>0,"흑자전환",IF(J23=0,"손익분기","미확인")),IF(I23<0,IF(J23>0,"흑자전환",IF(J23=0,"손익분기","적자지속")),IF(J23<0,"적자전환",IF(J23=0,-1,J23/I23-1)))),"미확인") | L23: =IF(ISNUMBER(G23),IF(G23>0,E23/G23,"적자"),"미산출") | M23: =IF(ISNUMBER(J23),IF(J23>0,E23/J23,"적자"),"미산출") | N23: =IF(원자료!O57="","미확인",원자료!O57) | O23: 16.7 | P23: 13.8 | Q23: 기존 / 원표 기준
A24: 78 | B24: 두산테스나 | C24: 131970 | D24: =원자료!I79 | E24: =D24*원자료!J79/100000000 | F24: =IF(원자료!T79="","미확인",원자료!T79) | G24: =IF(원자료!D79="","미확인",원자료!D79) | H24: =IF(AND(ISNUMBER(F24),ISNUMBER(G24)),IF(F24=0,IF(G24>0,"흑자전환",IF(G24=0,"손익분기","미확인")),IF(F24<0,IF(G24>0,"흑자전환",IF(G24=0,"손익분기","적자지속")),IF(G24<0,"적자전환",IF(G24=0,-1,G24/F24-1)))),"미확인") | I24: =IF(원자료!U79="","미확인",원자료!U79) | J24: =IF(원자료!E79="","미확인",원자료!E79) | K24: =IF(AND(ISNUMBER(I24),ISNUMBER(J24)),IF(I24=0,IF(J24>0,"흑자전환",IF(J24=0,"손익분기","미확인")),IF(I24<0,IF(J24>0,"흑자전환",IF(J24=0,"손익분기","적자지속")),IF(J24<0,"적자전환",IF(J24=0,-1,J24/I24-1)))),"미확인") | L24: =IF(ISNUMBER(G24),IF(G24>0,E24/G24,"적자"),"미산출") | M24: =IF(ISNUMBER(J24),IF(J24>0,E24/J24,"적자"),"미산출") | N24: =IF(원자료!O79="","미확인",원자료!O79) | O24: 26.4 | P24: 21.8 | Q24: 기존 / 원표 기준
A25: 87 | B25: 주성엔지니어링 | C25: 036930 | D25: =원자료!I92 | E25: =D25*원자료!J92/100000000 | F25: =IF(원자료!T92="","미확인",원자료!T92) | G25: =IF(원자료!D92="","미확인",원자료!D92) | H25: =IF(AND(ISNUMBER(F25),ISNUMBER(G25)),IF(F25=0,IF(G25>0,"흑자전환",IF(G25=0,"손익분기","미확인")),IF(F25<0,IF(G25>0,"흑자전환",IF(G25=0,"손익분기","적자지속")),IF(G25<0,"적자전환",IF(G25=0,-1,G25/F25-1)))),"미확인") | I25: =IF(원자료!U92="","미확인",원자료!U92) | J25: =IF(원자료!E92="","미확인",원자료!E92) | K25: =IF(AND(ISNUMBER(I25),ISNUMBER(J25)),IF(I25=0,IF(J25>0,"흑자전환",IF(J25=0,"손익분기","미확인")),IF(I25<0,IF(J25>0,"흑자전환",IF(J25=0,"손익분기","적자지속")),IF(J25<0,"적자전환",IF(J25=0,-1,J25/I25-1)))),"미확인") | L25: =IF(ISNUMBER(G25),IF(G25>0,E25/G25,"적자"),"미산출") | M25: =IF(ISNUMBER(J25),IF(J25>0,E25/J25,"적자"),"미산출") | N25: =IF(원자료!O92="","미확인",원자료!O92) | O25: 100.3 | P25: 83.9 | Q25: 기존 / 원표 기준
A26: 35 | B26: 예스티 | C26: 122640 | D26: =원자료!I46 | E26: =D26*원자료!J46/100000000 | F26: =IF(원자료!T46="","미확인",원자료!T46) | G26: =IF(원자료!D46="","미확인",원자료!D46) | H26: =IF(AND(ISNUMBER(F26),ISNUMBER(G26)),IF(F26=0,IF(G26>0,"흑자전환",IF(G26=0,"손익분기","미확인")),IF(F26<0,IF(G26>0,"흑자전환",IF(G26=0,"손익분기","적자지속")),IF(G26<0,"적자전환",IF(G26=0,-1,G26/F26-1)))),"미확인") | I26: =IF(원자료!U46="","미확인",원자료!U46) | J26: =IF(원자료!E46="","미확인",원자료!E46) | K26: =IF(AND(ISNUMBER(I26),ISNUMBER(J26)),IF(I26=0,IF(J26>0,"흑자전환",IF(J26=0,"손익분기","미확인")),IF(I26<0,IF(J26>0,"흑자전환",IF(J26=0,"손익분기","적자지속")),IF(J26<0,"적자전환",IF(J26=0,-1,J26/I26-1)))),"미확인") | L26: =IF(ISNUMBER(G26),IF(G26>0,E26/G26,"적자"),"미산출") | M26: =IF(ISNUMBER(J26),IF(J26>0,E26/J26,"적자"),"미산출") | N26: =IF(원자료!O46="","미확인",원자료!O46) | O26: 13.5 | P26: 10.2 | Q26: 기존 / 원표 기준
A27: 60 | B27: 기가비스 | C27: 420770 | D27: =원자료!I64 | E27: =D27*원자료!J64/100000000 | F27: =IF(원자료!T64="","미확인",원자료!T64) | G27: =IF(원자료!D64="","미확인",원자료!D64) | H27: =IF(AND(ISNUMBER(F27),ISNUMBER(G27)),IF(F27=0,IF(G27>0,"흑자전환",IF(G27=0,"손익분기","미확인")),IF(F27<0,IF(G27>0,"흑자전환",IF(G27=0,"손익분기","적자지속")),IF(G27<0,"적자전환",IF(G27=0,-1,G27/F27-1)))),"미확인") | I27: =IF(원자료!U64="","미확인",원자료!U64) | J27: =IF(원자료!E64="","미확인",원자료!E64) | K27: =IF(AND(ISNUMBER(I27),ISNUMBER(J27)),IF(I27=0,IF(J27>0,"흑자전환",IF(J27=0,"손익분기","미확인")),IF(I27<0,IF(J27>0,"흑자전환",IF(J27=0,"손익분기","적자지속")),IF(J27<0,"적자전환",IF(J27=0,-1,J27/I27-1)))),"미확인") | L27: =IF(ISNUMBER(G27),IF(G27>0,E27/G27,"적자"),"미산출") | M27: =IF(ISNUMBER(J27),IF(J27>0,E27/J27,"적자"),"미산출") | N27: =IF(원자료!O64="","미확인",원자료!O64) | O27: 20 | P27: 16.8 | Q27: 기존 / 원표 기준
A28: 41 | B28: 비씨엔씨 | C28: 146320 | D28: =원자료!I45 | E28: =D28*원자료!J45/100000000 | F28: =IF(원자료!T45="","미확인",원자료!T45) | G28: =IF(원자료!D45="","미확인",원자료!D45) | H28: =IF(AND(ISNUMBER(F28),ISNUMBER(G28)),IF(F28=0,IF(G28>0,"흑자전환",IF(G28=0,"손익분기","미확인")),IF(F28<0,IF(G28>0,"흑자전환",IF(G28=0,"손익분기","적자지속")),IF(G28<0,"적자전환",IF(G28=0,-1,G28/F28-1)))),"미확인") | I28: =IF(원자료!U45="","미확인",원자료!U45) | J28: =IF(원자료!E45="","미확인",원자료!E45) | K28: =IF(AND(ISNUMBER(I28),ISNUMBER(J28)),IF(I28=0,IF(J28>0,"흑자전환",IF(J28=0,"손익분기","미확인")),IF(I28<0,IF(J28>0,"흑자전환",IF(J28=0,"손익분기","적자지속")),IF(J28<0,"적자전환",IF(J28=0,-1,J28/I28-1)))),"미확인") | L28: =IF(ISNUMBER(G28),IF(G28>0,E28/G28,"적자"),"미산출") | M28: =IF(ISNUMBER(J28),IF(J28>0,E28/J28,"적자"),"미산출") | N28: =IF(원자료!O45="","미확인",원자료!O45) | O28: 13.5 | P28: 8.9 | Q28: 기존 / 원표 기준
A29: 33 | B29: 와이씨켐 | C29: 112290 | D29: =원자료!I41 | E29: =D29*원자료!J41/100000000 | F29: =IF(원자료!T41="","미확인",원자료!T41) | G29: =IF(원자료!D41="","미확인",원자료!D41) | H29: =IF(AND(ISNUMBER(F29),ISNUMBER(G29)),IF(F29=0,IF(G29>0,"흑자전환",IF(G29=0,"손익분기","미확인")),IF(F29<0,IF(G29>0,"흑자전환",IF(G29=0,"손익분기","적자지속")),IF(G29<0,"적자전환",IF(G29=0,-1,G29/F29-1)))),"미확인") | I29: =IF(원자료!U41="","미확인",원자료!U41) | J29: =IF(원자료!E41="","미확인",원자료!E41) | K29: =IF(AND(ISNUMBER(I29),ISNUMBER(J29)),IF(I29=0,IF(J29>0,"흑자전환",IF(J29=0,"손익분기","미확인")),IF(I29<0,IF(J29>0,"흑자전환",IF(J29=0,"손익분기","적자지속")),IF(J29<0,"적자전환",IF(J29=0,-1,J29/I29-1)))),"미확인") | L29: =IF(ISNUMBER(G29),IF(G29>0,E29/G29,"적자"),"미산출") | M29: =IF(ISNUMBER(J29),IF(J29>0,E29/J29,"적자"),"미산출") | N29: =IF(원자료!O41="","미확인",원자료!O41) | O29: 12.8 | P29: 11.1 | Q29: 기존 / 원표 기준
A30: 81 | B30: 삼성전기 | C30: 009150 | D30: =원자료!I97 | E30: =D30*원자료!J97/100000000 | F30: =IF(원자료!T97="","미확인",원자료!T97) | G30: =IF(원자료!D97="","미확인",원자료!D97) | H30: =IF(AND(ISNUMBER(F30),ISNUMBER(G30)),IF(F30=0,IF(G30>0,"흑자전환",IF(G30=0,"손익분기","미확인")),IF(F30<0,IF(G30>0,"흑자전환",IF(G30=0,"손익분기","적자지속")),IF(G30<0,"적자전환",IF(G30=0,-1,G30/F30-1)))),"미확인") | I30: =IF(원자료!U97="","미확인",원자료!U97) | J30: =IF(원자료!E97="","미확인",원자료!E97) | K30: =IF(AND(ISNUMBER(I30),ISNUMBER(J30)),IF(I30=0,IF(J30>0,"흑자전환",IF(J30=0,"손익분기","미확인")),IF(I30<0,IF(J30>0,"흑자전환",IF(J30=0,"손익분기","적자지속")),IF(J30<0,"적자전환",IF(J30=0,-1,J30/I30-1)))),"미확인") | L30: =IF(ISNUMBER(G30),IF(G30>0,E30/G30,"적자"),"미산출") | M30: =IF(ISNUMBER(J30),IF(J30>0,E30/J30,"적자"),"미산출") | N30: =IF(원자료!O97="","미확인",원자료!O97) | Q30: 추가 / 지배순이익
A31: 8 | B31: 유니테스트 | C31: 086390 | D31: =원자료!I19 | E31: =D31*원자료!J19/100000000 | F31: =IF(원자료!T19="","미확인",원자료!T19) | G31: =IF(원자료!D19="","미확인",원자료!D19) | H31: =IF(AND(ISNUMBER(F31),ISNUMBER(G31)),IF(F31=0,IF(G31>0,"흑자전환",IF(G31=0,"손익분기","미확인")),IF(F31<0,IF(G31>0,"흑자전환",IF(G31=0,"손익분기","적자지속")),IF(G31<0,"적자전환",IF(G31=0,-1,G31/F31-1)))),"미확인") | I31: =IF(원자료!U19="","미확인",원자료!U19) | J31: =IF(원자료!E19="","미확인",원자료!E19) | K31: =IF(AND(ISNUMBER(I31),ISNUMBER(J31)),IF(I31=0,IF(J31>0,"흑자전환",IF(J31=0,"손익분기","미확인")),IF(I31<0,IF(J31>0,"흑자전환",IF(J31=0,"손익분기","적자지속")),IF(J31<0,"적자전환",IF(J31=0,-1,J31/I31-1)))),"미확인") | L31: =IF(ISNUMBER(G31),IF(G31>0,E31/G31,"적자"),"미산출") | M31: =IF(ISNUMBER(J31),IF(J31>0,E31/J31,"적자"),"미산출") | N31: =IF(원자료!O19="","미확인",원자료!O19) | O31: 7.8 | P31: 6.2 | Q31: 기존 / 원표 기준
A32: 73 | B32: 에프에스티 | C32: 036810 | D32: =원자료!I84 | E32: =D32*원자료!J84/100000000 | F32: =IF(원자료!T84="","미확인",원자료!T84) | G32: =IF(원자료!D84="","미확인",원자료!D84) | H32: =IF(AND(ISNUMBER(F32),ISNUMBER(G32)),IF(F32=0,IF(G32>0,"흑자전환",IF(G32=0,"손익분기","미확인")),IF(F32<0,IF(G32>0,"흑자전환",IF(G32=0,"손익분기","적자지속")),IF(G32<0,"적자전환",IF(G32=0,-1,G32/F32-1)))),"미확인") | I32: =IF(원자료!U84="","미확인",원자료!U84) | J32: =IF(원자료!E84="","미확인",원자료!E84) | K32: =IF(AND(ISNUMBER(I32),ISNUMBER(J32)),IF(I32=0,IF(J32>0,"흑자전환",IF(J32=0,"손익분기","미확인")),IF(I32<0,IF(J32>0,"흑자전환",IF(J32=0,"손익분기","적자지속")),IF(J32<0,"적자전환",IF(J32=0,-1,J32/I32-1)))),"미확인") | L32: =IF(ISNUMBER(G32),IF(G32>0,E32/G32,"적자"),"미산출") | M32: =IF(ISNUMBER(J32),IF(J32>0,E32/J32,"적자"),"미산출") | N32: =IF(원자료!O84="","미확인",원자료!O84) | O32: 28.6 | P32: 16.4 | Q32: 기존 / 원표 기준
A33: 39 | B33: 오킨스전자 | C33: 080580 | D33: =원자료!I43 | E33: =D33*원자료!J43/100000000 | F33: =IF(원자료!T43="","미확인",원자료!T43) | G33: =IF(원자료!D43="","미확인",원자료!D43) | H33: =IF(AND(ISNUMBER(F33),ISNUMBER(G33)),IF(F33=0,IF(G33>0,"흑자전환",IF(G33=0,"손익분기","미확인")),IF(F33<0,IF(G33>0,"흑자전환",IF(G33=0,"손익분기","적자지속")),IF(G33<0,"적자전환",IF(G33=0,-1,G33/F33-1)))),"미확인") | I33: =IF(원자료!U43="","미확인",원자료!U43) | J33: =IF(원자료!E43="","미확인",원자료!E43) | K33: =IF(AND(ISNUMBER(I33),ISNUMBER(J33)),IF(I33=0,IF(J33>0,"흑자전환",IF(J33=0,"손익분기","미확인")),IF(I33<0,IF(J33>0,"흑자전환",IF(J33=0,"손익분기","적자지속")),IF(J33<0,"적자전환",IF(J33=0,-1,J33/I33-1)))),"미확인") | L33: =IF(ISNUMBER(G33),IF(G33>0,E33/G33,"적자"),"미산출") | M33: =IF(ISNUMBER(J33),IF(J33>0,E33/J33,"적자"),"미산출") | N33: =IF(원자료!O43="","미확인",원자료!O43) | O33: 13 | P33: 10.6 | Q33: 기존 / 원표 기준
A34: 26 | B34: 펨트론 | C34: 168360 | D34: =원자료!I40 | E34: =D34*원자료!J40/100000000 | F34: =IF(원자료!T40="","미확인",원자료!T40) | G34: =IF(원자료!D40="","미확인",원자료!D40) | H34: =IF(AND(ISNUMBER(F34),ISNUMBER(G34)),IF(F34=0,IF(G34>0,"흑자전환",IF(G34=0,"손익분기","미확인")),IF(F34<0,IF(G34>0,"흑자전환",IF(G34=0,"손익분기","적자지속")),IF(G34<0,"적자전환",IF(G34=0,-1,G34/F34-1)))),"미확인") | I34: =IF(원자료!U40="","미확인",원자료!U40) | J34: =IF(원자료!E40="","미확인",원자료!E40) | K34: =IF(AND(ISNUMBER(I34),ISNUMBER(J34)),IF(I34=0,IF(J34>0,"흑자전환",IF(J34=0,"손익분기","미확인")),IF(I34<0,IF(J34>0,"흑자전환",IF(J34=0,"손익분기","적자지속")),IF(J34<0,"적자전환",IF(J34=0,-1,J34/I34-1)))),"미확인") | L34: =IF(ISNUMBER(G34),IF(G34>0,E34/G34,"적자"),"미산출") | M34: =IF(ISNUMBER(J34),IF(J34>0,E34/J34,"적자"),"미산출") | N34: =IF(원자료!O40="","미확인",원자료!O40) | O34: 12.7 | P34: 9.9 | Q34: 기존 / 원표 기준
A35: 65 | B35: 후성 | C35: 093370 | D35: =원자료!I70 | E35: =D35*원자료!J70/100000000 | F35: =IF(원자료!T70="","미확인",원자료!T70) | G35: =IF(원자료!D70="","미확인",원자료!D70) | H35: =IF(AND(ISNUMBER(F35),ISNUMBER(G35)),IF(F35=0,IF(G35>0,"흑자전환",IF(G35=0,"손익분기","미확인")),IF(F35<0,IF(G35>0,"흑자전환",IF(G35=0,"손익분기","적자지속")),IF(G35<0,"적자전환",IF(G35=0,-1,G35/F35-1)))),"미확인") | I35: =IF(원자료!U70="","미확인",원자료!U70) | J35: =IF(원자료!E70="","미확인",원자료!E70) | K35: =IF(AND(ISNUMBER(I35),ISNUMBER(J35)),IF(I35=0,IF(J35>0,"흑자전환",IF(J35=0,"손익분기","미확인")),IF(I35<0,IF(J35>0,"흑자전환",IF(J35=0,"손익분기","적자지속")),IF(J35<0,"적자전환",IF(J35=0,-1,J35/I35-1)))),"미확인") | L35: =IF(ISNUMBER(G35),IF(G35>0,E35/G35,"적자"),"미산출") | M35: =IF(ISNUMBER(J35),IF(J35>0,E35/J35,"적자"),"미산출") | N35: =IF(원자료!O70="","미확인",원자료!O70) | O35: 21.4 | P35: 14.5 | Q35: 기존 / †
A36: 46 | B36: 큐알티 | C36: 405100 | D36: =원자료!I42 | E36: =D36*원자료!J42/100000000 | F36: =IF(원자료!T42="","미확인",원자료!T42) | G36: =IF(원자료!D42="","미확인",원자료!D42) | H36: =IF(AND(ISNUMBER(F36),ISNUMBER(G36)),IF(F36=0,IF(G36>0,"흑자전환",IF(G36=0,"손익분기","미확인")),IF(F36<0,IF(G36>0,"흑자전환",IF(G36=0,"손익분기","적자지속")),IF(G36<0,"적자전환",IF(G36=0,-1,G36/F36-1)))),"미확인") | I36: =IF(원자료!U42="","미확인",원자료!U42) | J36: =IF(원자료!E42="","미확인",원자료!E42) | K36: =IF(AND(ISNUMBER(I36),ISNUMBER(J36)),IF(I36=0,IF(J36>0,"흑자전환",IF(J36=0,"손익분기","미확인")),IF(I36<0,IF(J36>0,"흑자전환",IF(J36=0,"손익분기","적자지속")),IF(J36<0,"적자전환",IF(J36=0,-1,J36/I36-1)))),"미확인") | L36: =IF(ISNUMBER(G36),IF(G36>0,E36/G36,"적자"),"미산출") | M36: =IF(ISNUMBER(J36),IF(J36>0,E36/J36,"적자"),"미산출") | N36: =IF(원자료!O42="","미확인",원자료!O42) | O36: 12.8 | P36: 9.5 | Q36: 기존 / 원표 기준
A37: 43 | B37: 네오티스 | C37: 085910 | D37: =원자료!I94 | E37: =D37*원자료!J94/100000000 | F37: =IF(원자료!T94="","미확인",원자료!T94) | G37: =IF(원자료!D94="","미확인",원자료!D94) | H37: =IF(AND(ISNUMBER(F37),ISNUMBER(G37)),IF(F37=0,IF(G37>0,"흑자전환",IF(G37=0,"손익분기","미확인")),IF(F37<0,IF(G37>0,"흑자전환",IF(G37=0,"손익분기","적자지속")),IF(G37<0,"적자전환",IF(G37=0,-1,G37/F37-1)))),"미확인") | I37: =IF(원자료!U94="","미확인",원자료!U94) | J37: =IF(원자료!E94="","미확인",원자료!E94) | K37: =IF(AND(ISNUMBER(I37),ISNUMBER(J37)),IF(I37=0,IF(J37>0,"흑자전환",IF(J37=0,"손익분기","미확인")),IF(I37<0,IF(J37>0,"흑자전환",IF(J37=0,"손익분기","적자지속")),IF(J37<0,"적자전환",IF(J37=0,-1,J37/I37-1)))),"미확인") | L37: =IF(ISNUMBER(G37),IF(G37>0,E37/G37,"적자"),"미산출") | M37: =IF(ISNUMBER(J37),IF(J37>0,E37/J37,"적자"),"미산출") | N37: =IF(원자료!O94="","미확인",원자료!O94) | Q37: 추가 / 지배순이익
A38: 50 | B38: 심텍 | C38: 222800 | D38: =원자료!I58 | E38: =D38*원자료!J58/100000000 | F38: =IF(원자료!T58="","미확인",원자료!T58) | G38: =IF(원자료!D58="","미확인",원자료!D58) | H38: =IF(AND(ISNUMBER(F38),ISNUMBER(G38)),IF(F38=0,IF(G38>0,"흑자전환",IF(G38=0,"손익분기","미확인")),IF(F38<0,IF(G38>0,"흑자전환",IF(G38=0,"손익분기","적자지속")),IF(G38<0,"적자전환",IF(G38=0,-1,G38/F38-1)))),"미확인") | I38: =IF(원자료!U58="","미확인",원자료!U58) | J38: =IF(원자료!E58="","미확인",원자료!E58) | K38: =IF(AND(ISNUMBER(I38),ISNUMBER(J38)),IF(I38=0,IF(J38>0,"흑자전환",IF(J38=0,"손익분기","미확인")),IF(I38<0,IF(J38>0,"흑자전환",IF(J38=0,"손익분기","적자지속")),IF(J38<0,"적자전환",IF(J38=0,-1,J38/I38-1)))),"미확인") | L38: =IF(ISNUMBER(G38),IF(G38>0,E38/G38,"적자"),"미산출") | M38: =IF(ISNUMBER(J38),IF(J38>0,E38/J38,"적자"),"미산출") | N38: =IF(원자료!O58="","미확인",원자료!O58) | O38: 17.6 | P38: 13.6 | Q38: 기존 / 원표 기준
A39: 85 | B39: RF머트리얼즈 | C39: 327260 | D39: =원자료!I96 | E39: =D39*원자료!J96/100000000 | F39: =IF(원자료!T96="","미확인",원자료!T96) | G39: =IF(원자료!D96="","미확인",원자료!D96) | H39: =IF(AND(ISNUMBER(F39),ISNUMBER(G39)),IF(F39=0,IF(G39>0,"흑자전환",IF(G39=0,"손익분기","미확인")),IF(F39<0,IF(G39>0,"흑자전환",IF(G39=0,"손익분기","적자지속")),IF(G39<0,"적자전환",IF(G39=0,-1,G39/F39-1)))),"미확인") | I39: =IF(원자료!U96="","미확인",원자료!U96) | J39: =IF(원자료!E96="","미확인",원자료!E96) | K39: =IF(AND(ISNUMBER(I39),ISNUMBER(J39)),IF(I39=0,IF(J39>0,"흑자전환",IF(J39=0,"손익분기","미확인")),IF(I39<0,IF(J39>0,"흑자전환",IF(J39=0,"손익분기","적자지속")),IF(J39<0,"적자전환",IF(J39=0,-1,J39/I39-1)))),"미확인") | L39: =IF(ISNUMBER(G39),IF(G39>0,E39/G39,"적자"),"미산출") | M39: =IF(ISNUMBER(J39),IF(J39>0,E39/J39,"적자"),"미산출") | N39: =IF(원자료!O96="","미확인",원자료!O96) | Q39: 추가 / 지배순이익
A40: 7 | B40: 에프엔에스테크 | C40: 083500 | D40: =원자료!I15 | E40: =D40*원자료!J15/100000000 | F40: =IF(원자료!T15="","미확인",원자료!T15) | G40: =IF(원자료!D15="","미확인",원자료!D15) | H40: =IF(AND(ISNUMBER(F40),ISNUMBER(G40)),IF(F40=0,IF(G40>0,"흑자전환",IF(G40=0,"손익분기","미확인")),IF(F40<0,IF(G40>0,"흑자전환",IF(G40=0,"손익분기","적자지속")),IF(G40<0,"적자전환",IF(G40=0,-1,G40/F40-1)))),"미확인") | I40: =IF(원자료!U15="","미확인",원자료!U15) | J40: =IF(원자료!E15="","미확인",원자료!E15) | K40: =IF(AND(ISNUMBER(I40),ISNUMBER(J40)),IF(I40=0,IF(J40>0,"흑자전환",IF(J40=0,"손익분기","미확인")),IF(I40<0,IF(J40>0,"흑자전환",IF(J40=0,"손익분기","적자지속")),IF(J40<0,"적자전환",IF(J40=0,-1,J40/I40-1)))),"미확인") | L40: =IF(ISNUMBER(G40),IF(G40>0,E40/G40,"적자"),"미산출") | M40: =IF(ISNUMBER(J40),IF(J40>0,E40/J40,"적자"),"미산출") | N40: =IF(원자료!O15="","미확인",원자료!O15) | O40: 6.4 | P40: 4.3 | Q40: 기존 / †
A41: 3 | B41: 엠케이전자 | C41: 033160 | D41: =원자료!I12 | E41: =D41*원자료!J12/100000000 | F41: =IF(원자료!T12="","미확인",원자료!T12) | G41: =IF(원자료!D12="","미확인",원자료!D12) | H41: =IF(AND(ISNUMBER(F41),ISNUMBER(G41)),IF(F41=0,IF(G41>0,"흑자전환",IF(G41=0,"손익분기","미확인")),IF(F41<0,IF(G41>0,"흑자전환",IF(G41=0,"손익분기","적자지속")),IF(G41<0,"적자전환",IF(G41=0,-1,G41/F41-1)))),"미확인") | I41: =IF(원자료!U12="","미확인",원자료!U12) | J41: =IF(원자료!E12="","미확인",원자료!E12) | K41: =IF(AND(ISNUMBER(I41),ISNUMBER(J41)),IF(I41=0,IF(J41>0,"흑자전환",IF(J41=0,"손익분기","미확인")),IF(I41<0,IF(J41>0,"흑자전환",IF(J41=0,"손익분기","적자지속")),IF(J41<0,"적자전환",IF(J41=0,-1,J41/I41-1)))),"미확인") | L41: =IF(ISNUMBER(G41),IF(G41>0,E41/G41,"적자"),"미산출") | M41: =IF(ISNUMBER(J41),IF(J41>0,E41/J41,"적자"),"미산출") | N41: =IF(원자료!O12="","미확인",원자료!O12) | O41: 4.3 | P41: 2.6 | Q41: 기존 / †
...

Sheet 원자료
A2: 원표 및 조회 입력값
A3: 원표 시총은 조원 단위 반올림을 포함. 재계산에는 사용하지 않음. 추가 종목 순이익은 지배주주 기준. | O3: 27E ROE: 10/14 직접 제공값 79개 대조 일치. 미확인 11개: 자기자본 미확인 7, 출처 불일치 1, 이익 추정도 미확인 3.
A4: 2026-10-15 KRX 정규장 종가. 시세 응답의 closePrice 사용. NXT 시간외 overPrice 제외. | O4: ROE = 2027E 지배주주순이익 ÷ 2026말·2027말 평균 지배주주자본. 별도는 별도 기준. PER/POR 존재만으로 산출 가능하지 않음.
O5: 기존 원표 이익(10/10)과 ROE(10/14)는 기준일이 다름. 원표 † 순이익과 ROE 지배주주순이익의 기준 차이에 유의. 재검토 사유는 S열.
A9: 종목 | B9: 코드 | C9: 원표 시총 | D9: 27E 순이익 | E9: 27E 영업이익 | F9: 원표 PER | G9: 원표 POR | H9: † | I9: 10/15 종가 | J9: 상장주식 수 | K9: 주가 기준 | L9: 실적 출처 | M9: 시세 출처 | N9: 종가 확인 출처 | O9: 27E ROE | P9: ROE 재무기준 | Q9: ROE 기준일 | R9: ROE 출처 | S9: ROE 재검토 결과 (10/15) | T9: 26E 순이익 (억원) | U9: 26E 영업이익 (억원) | V9: 26E 회계기준 | W9: 26E 출처 (10/14) | X9: 27E 추정치 교차점검
A10: 삼성전자 | B10: 005930 | C10: 14640000 | D10: 4500000 | E10: 5550000 | F10: 3.3 | G10: 2.6 | I10: 207500 | J10: 5846278608 | K10: 2026-10-15 정규장 종가 | L10: 사용자 첨부 IMG_7104~7108 / 원문 https://m.blog.naver.com/stockvera/224440085158 | M10: https://polling.finance.naver.com/api/realtime/domestic/stock/005930 | N10: https://polling.finance.naver.com/api/realtime/domestic/stock/005930 | O10: 0.5032 | P10: IFRS연결 | Q10: 2026-10-14 | R10: https://comp.wisereport.co.kr/company/ajax/c1050001_data.aspx?flag=2&cmp_cd=005930&finGubun=MAIN&frq=0&sDT=20261014&chartType=image | S10: 2027.12(E) ROE 직접 제공값과 대조 일치. 백분율 단위·종목코드 확인. | T10: 3036391 | U10: 3716393.4 | V10: IFRS연결 | W10: https://comp.wisereport.co.kr/company/ajax/c1050001_data.aspx?flag=2&cmp_cd=005930&finGubun=MAIN&frq=0&sDT=20261014&chartType=image | X10: 27E 원표와 FnGuide 차이 10% 이내 또는 비교 자료 없음
A11: SK하이닉스 | B11: 000660 | C11: 11720000 | D11: 3260000 | E11: 4020000 | F11: 3.6 | G11: 2.9 | I11: 1238000 | J11: 730492365 | K11: 2026-10-15 정규장 종가 | L11: 사용자 첨부 IMG_7104~7108 / 원문 https://m.blog.naver.com/stockvera/224440085158 | M11: https://polling.finance.naver.com/api/realtime/domestic/stock/000660 | N11: https://polling.finance.naver.com/api/realtime/domestic/stock/000660 | O11: 0.6211 | P11: IFRS연결 | Q11: 2026-10-14 | R11: https://comp.wisereport.co.kr/company/ajax/c1050001_data.aspx?flag=2&cmp_cd=000660&finGubun=MAIN&frq=0&sDT=20261014&chartType=image | S11: 2027.12(E) ROE 직접 제공값과 대조 일치. 백분율 단위·종목코드 확인. | T11: 2557448.7 | U11: 2625689.8 | V11: IFRS연결 | W11: https://comp.wisereport.co.kr/company/ajax/c1050001_data.aspx?flag=2&cmp_cd=000660&finGubun=MAIN&frq=0&sDT=20261014&chartType=image | X11: 27E 원표와 FnGuide 차이 10% 이내 또는 비교 자료 없음
A12: 엠케이전자 | B12: 033160 | C12: 4618 | D12: 1079 | E12: 1744 | F12: 4.3 | G12: 2.6 | H12: † | I12: 14690 | J12: 24564058 | K12: 2026-10-15 정규장 종가 | L12: 사용자 첨부 IMG_7104~7108 / 원문 https://m.blog.naver.com/stockvera/224440085158 | M12: https://polling.finance.naver.com/api/realtime/domestic/stock/033160 | N12: https://polling.finance.naver.com/api/realtime/domestic/stock/033160 | O12: 미확인 | P12: IFRS연결 | Q12: 2026-10-14 | R12: https://comp.wisereport.co.kr/company/ajax/c1050001_data.aspx?flag=2&cmp_cd=033160&finGubun=MAIN&frq=0&sDT=20261014&chartType=image | S12: 2027년 이익 추정치는 있으나 2026/2027 BPS·ROE 미제공. 평균 예상 자기자본 미확인으로 계산 보류. 주재무·연결·별도 및 기업현황 화면 재조회. 별도 ROE 21.64%는 확인되나 연결 기준과 달라 대체하지 않음. | T12: 647.5 | U12: 1077.33 | V12: IFRS연결 | W12: https://comp.wisereport.co.kr/company/ajax/c1050001_data.aspx?flag=2&cmp_cd=033160&finGubun=MAIN&frq=0&sDT=20261014&chartType=image | X12: 순이익: 기존 27E 1,079.00억원 vs FnGuide 849.00억원 (-21.3%); 영업이익: 기존 27E 1,744.00억원 vs FnGuide 1,559.00억원 (-10.6%)
A13: 세보엠이씨 | B13: 011560 | C13: 2123 | D13: 491 | E13: 580 | F13: 4.3 | G13: 3.7 | I13: 19930 | J13: 10084872 | K13: 2026-10-15 정규장 종가 | L13: 사용자 첨부 IMG_7104~7108 / 원문 https://m.blog.naver.com/stockvera/224440085158 | M13: https://polling.finance.naver.com/api/realtime/domestic/stock/011560 | N13: https://polling.finance.naver.com/api/realtime/domestic/stock/011560 | O13: 0.1475 | P13: IFRS연결 | Q13: 2026-10-14 | R13: https://comp.wisereport.co.kr/company/ajax/c1050001_data.aspx?flag=2&cmp_cd=011560&finGubun=MAIN&frq=0&sDT=20261014&chartType=image | S13: 2027.12(E) ROE 직접 제공값과 대조 일치. 백분율 단위·종목코드 확인. | T13: 471 | U13: 559 | V13: IFRS연결 | W13: https://comp.wisereport.co.kr/company/ajax/c1050001_data.aspx?flag=2&cmp_cd=011560&finGubun=MAIN&frq=0&sDT=20261014&chartType=image | X13: 27E 원표와 FnGuide 차이 10% 이내 또는 비교 자료 없음
A14: 케이씨 | B14: 029460 | C14: 4953 | D14: 830 | E14: 973 | F14: 6 | G14: 5.1 | I14: 36800 | J14: 11020535 | K14: 2026-10-15 정규장 종가 | L14: 사용자 첨부 IMG_7104~7108 / 원문 https://m.blog.naver.com/stockvera/224440085158 | M14: https://polling.finance.naver.com/api/realtime/domestic/stock/029460 | N14: https://polling.finance.naver.com/api/realtime/domestic/stock/029460 | O14: 미확인 | P14: IFRS연결 | Q14: 2026-10-14 | R14: https://comp.wisereport.co.kr/company/ajax/c1050001_data.aspx?flag=2&cmp_cd=029460&finGubun=MAIN&frq=0&sDT=20261014&chartType=image | S14: 2027년 이익 추정치는 있으나 2026/2027 BPS·ROE 미제공. 평균 예상 자기자본 미확인으로 계산 보류. 주재무·연결·별도 및 기업현황 화면 재조회. | T14: 740 | U14: 756 | V14: IFRS연결 | W14: https://comp.wisereport.co.kr/company/ajax/c1050001_data.aspx?flag=2&cmp_cd=029460&finGubun=MAIN&frq=0&sDT=20261014&chartType=image | X14: 27E 원표와 FnGuide 차이 10% 이내 또는 비교 자료 없음
A15: 에프엔에스테크 | B15: 083500 | C15: 1251 | D15: 195 | E15: 288 | F15: 6.4 | G15: 4.3 | H15: † | I15: 13050 | J15: 8306377 | K15: 2026-10-15 정규장 종가 | L15: 사용자 첨부 IMG_7104~7108 / 원문 https://m.blog.naver.com/stockvera/224440085158 | M15: https://polling.finance.naver.com/api/realtime/domestic/stock/083500 | N15: https://polling.finance.naver.com/api/realtime/domestic/stock/083500 | O15: 0.1884 | P15: IFRS연결 | Q15: 2026-10-14 | R15: https://comp.wisereport.co.kr/company/ajax/c1050001_data.aspx?flag=2&cmp_cd=083500&finGubun=MAIN&frq=0&sDT=20261014&chartType=image | S15: 2027.12(E) ROE 직접 제공값과 대조 일치. 백분율 단위·종목코드 확인. | T15: 116 | U15: 161 | V15: IFRS연결 | W15: https://comp.wisereport.co.kr/company/ajax/c1050001_data.aspx?flag=2&cmp_cd=083500&finGubun=MAIN&frq=0&sDT=20261014&chartType=image | X15: 27E 원표와 FnGuide 차이 10% 이내 또는 비교 자료 없음
A16: 원익머트리얼즈 | B16: 104830 | C16: 5125 | D16: 772 | E16: 931 | F16: 6.6 | G16: 5.5 | I16: 36150 | J16: 12608000 | K16: 2026-10-15 정규장 종가 | L16: 사용자 첨부 IMG_7104~7108 / 원문 https://m.blog.naver.com/stockvera/224440085158 | M16: https://polling.finance.naver.com/api/realtime/domestic/stock/104830 | N16: https://polling.finance.naver.com/api/realtime/domestic/stock/104830 | O16: 0.1261 | P16: IFRS연결 | Q16: 2026-10-14 | R16: https://comp.wisereport.co.kr/company/ajax/c1050001_data.aspx?flag=2&cmp_cd=104830&finGubun=MAIN&frq=0&sDT=20261014&chartType=image | S16: 2027.12(E) ROE 직접 제공값과 대조 일치. 백분율 단위·종목코드 확인. | T16: 589.67 | U16: 679 | V16: IFRS연결 | W16: https://comp.wisereport.co.kr/company/ajax/c1050001_data.aspx?flag=2&cmp_cd=104830&finGubun=MAIN&frq=0&sDT=20261014&chartType=image | X16: 27E 원표와 FnGuide 차이 10% 이내 또는 비교 자료 없음
A17: 케이엔제이 | B17: 272110 | C17: 2568 | D17: 366 | E17: 444 | F17: 7 | G17: 5.8 | I17: 25050 | J17: 8025395 | K17: 2026-10-15 정규장 종가 | L17: 사용자 첨부 IMG_7104~7108 / 원문 https://m.blog.naver.com/stockvera/224440085158 | M17: https://polling.finance.naver.com/api/realtime/domestic/stock/272110 | N17: https://polling.finance.naver.com/api/realtime/domestic/stock/272110 | O17: 0.2633 | P17: IFRS연결 | Q17: 2026-10-14 | R17: https://comp.wisereport.co.kr/company/ajax/c1050001_data.aspx?flag=2&cmp_cd=272110&finGubun=MAIN&frq=0&sDT=20261014&chartType=image | S17: 2027.12(E) ROE 직접 제공값과 대조 일치. 백분율 단위·종목코드 확인. | T17: 250 | U17: 312 | V17: IFRS연결 | W17: https://comp.wisereport.co.kr/company/ajax/c1050001_data.aspx?flag=2&cmp_cd=272110&finGubun=MAIN&frq=0&sDT=20261014&chartType=image | X17: 27E 원표와 FnGuide 차이 10% 이내 또는 비교 자료 없음
A18: 지앤비에스 에코 | B18: 382800 | C18: 2060 | D18: 278 | E18: 322 | F18: 7.4 | G18: 6.4 | I18: 5240 | J18: 31831041 | K18: 2026-10-15 정규장 종가 | L18: 사용자 첨부 IMG_7104~7108 / 원문 https://m.blog.naver.com/stockvera/224440085158 | M18: https://polling.finance.naver.com/api/realtime/domestic/stock/382800 | N18: https://polling.finance.naver.com/api/realtime/domestic/stock/382800 | O18: 0.1858 | P18: IFRS연결 | Q18: 2026-10-14 | R18: https://comp.wisereport.co.kr/company/ajax/c1050001_data.aspx?flag=2&cmp_cd=382800&finGubun=MAIN&frq=0&sDT=20261014&chartType=image | S18: 2027.12(E) ROE 직접 제공값과 대조 일치. 백분율 단위·종목코드 확인. | T18: 242.33 | U18: 265 | V18: IFRS연결 | W18: https://comp.wisereport.co.kr/company/ajax/c1050001_data.aspx?flag=2&cmp_cd=382800&finGubun=MAIN&frq=0&sDT=20261014&chartType=image | X18: 27E 원표와 FnGuide 차이 10% 이내 또는 비교 자료 없음
A19: 유니테스트 | B19: 086390 | C19: 2868 | D19: 369 | E19: 460 | F19: 7.8 | G19: 6.2 | I19: 10190 | J19: 21134126 | K19: 2026-10-15 정규장 종가 | L19: 사용자 첨부 IMG_7104~7108 / 원문 https://m.blog.naver.com/stockvera/224440085158 | M19: https://polling.finance.naver.com/api/realtime/domestic/stock/086390 | N19: https://polling.finance.naver.com/api/realtime/domestic/stock/086390 | O19: 0.2771 | P19: IFRS연결 | Q19: 2026-10-14 | R19: https://comp.wisereport.co.kr/company/ajax/c1050001_data.aspx?flag=2&cmp_cd=086390&finGubun=MAIN&frq=0&sDT=20261014&chartType=image | S19: 2027.12(E) ROE 직접 제공값과 대조 일치. 백분율 단위·종목코드 확인. | T19: 195.75 | U19: 218.7 | V19: IFRS연결 | W19: https://comp.wisereport.co.kr/company/ajax/c1050001_data.aspx?flag=2&cmp_cd=086390&finGubun=MAIN&frq=0&sDT=20261014&chartType=image | X19: 27E 원표와 FnGuide 차이 10% 이내 또는 비교 자료 없음
A20: 이엔에프테크놀로지 | B20: 102710 | C20: 6987 | D20: 873 | E20: 1223 | F20: 8 | G20: 5.7 | I20: 41050 | J20: 14287836 | K20: 2026-10-15 정규장 종가 | L20: 사용자 첨부 IMG_7104~7108 / 원문 https://m.blog.naver.com/stockvera/224440085158 | M20: https://polling.finance.naver.com/api/realtime/domestic/stock/102710 | N20: https://polling.finance.naver.com/api/realtime/domestic/stock/102710 | O20: 0.1584 | P20: IFRS연결 | Q20: 2026-10-14 | R20: https://comp.wisereport.co.kr/company/ajax/c1050001_data.aspx?flag=2&cmp_cd=102710&finGubun=MAIN&frq=0&sDT=20261014&chartType=image | S20: 2027.12(E) ROE 직접 제공값과 대조 일치. 백분율 단위·종목코드 확인. | T20: 660.5 | U20: 965.75 | V20: IFRS연결 | W20: https://comp.wisereport.co.kr/company/ajax/c1050001_data.aspx?flag=2&cmp_cd=102710&finGubun=MAIN&frq=0&sDT=20261014&chartType=image | X20: 27E 원표와 FnGuide 차이 10% 이내 또는 비교 자료 없음
A21: 텔레칩스 | B21: 054450 | C21: 1467 | D21: 180 | E21: 224 | F21: 8.1 | G21: 6.6 | I21: 7980 | J21: 15144233 | K21: 2026-10-15 정규장 종가 | L21: 사용자 첨부 IMG_7104~7108 / 원문 https://m.blog.naver.com/stockvera/224440085158 | M21: https://polling.finance.naver.com/api/realtime/domestic/stock/054450 | N21: https://polling.finance.naver.com/api/realtime/domestic/stock/054450 | O21: 0.1187 | P21: IFRS연결 | Q21: 2026-10-14 | R21: https://comp.wisereport.co.kr/company/ajax/c1050001_data.aspx?flag=2&cmp_cd=054450&finGubun=MAIN&frq=0&sDT=20261014&chartType=image | S21: 2027.12(E) ROE 직접 제공값과 대조 일치. 백분율 단위·종목코드 확인. | T21: 30.5 | U21: 171.5 | V21: IFRS연결 | W21: https://comp.wisereport.co.kr/company/ajax/c1050001_data.aspx?flag=2&cmp_cd=054450&finGubun=MAIN&frq=0&sDT=20261014&chartType=image | X21: 27E 원표와 FnGuide 차이 10% 이내 또는 비교 자료 없음
A22: 싸이맥스 | B22: 160980 | C22: 2928 | D22: 360 | E22: 457 | F22: 8.1 | G22: 6.4 | I22: 20000 | J22: 10924243 | K22: 2026-10-15 정규장 종가 | L22: 사용자 첨부 IMG_7104~7108 / 원문 https://m.blog.naver.com/stockvera/224440085158 | M22: https://polling.finance.naver.com/api/realtime/domestic/stock/160980 | N22: https://polling.finance.naver.com/api/realtime/domestic/stock/160980 | O22: 0.1552 | P22: IFRS연결 | Q22: 2026-10-14 | R22: https://comp.wisereport.co.kr/company/ajax/c1050001_data.aspx?flag=2&cmp_cd=160980&finGubun=MAIN&frq=0&sDT=20261014&chartType=image | S22: 2027.12(E) ROE 직접 제공값과 대조 일치. 백분율 단위·종목코드 확인. | T22: 284 | U22: 359 | V22: IFRS연결 | W22: https://comp.wisereport.co.kr/company/ajax/c1050001_data.aspx?flag=2&cmp_cd=160980&finGubun=MAIN&frq=0&sDT=20261014&chartType=image | X22: 27E 원표와 FnGuide 차이 10% 이내 또는 비교 자료 없음
A23: 한솔아이원스 | B23: 114810 | C23: 4129 | D23: 477 | E23: 613 | F23: 8.7 | G23: 6.7 | I23: 11810 | J23: 28143174 | K23: 2026-10-15 정규장 종가 | L23: 사용자 첨부 IMG_7104~7108 / 원문 https://m.blog.naver.com/stockvera/224440085158 | M23: https://polling.finance.naver.com/api/realtime/domestic/stock/114810 | N23: https://polling.finance.naver.com/api/realtime/domestic/stock/114810 | O23: 미확인 | P23: IFRS연결 | Q23: 2026-10-14 | R23: https://comp.wisereport.co.kr/company/ajax/c1050001_data.aspx?flag=2&cmp_cd=114810&finGubun=MAIN&frq=0&sDT=20261014&chartType=image | S23: 2027년 이익 추정치는 있으나 2026/2027 BPS·ROE 미제공. 평균 예상 자기자본 미확인으로 계산 보류. 주재무·연결·별도 및 기업현황 화면 재조회. | T23: 337 | U23: 427 | V23: IFRS연결 | W23: https://comp.wisereport.co.kr/company/ajax/c1050001_data.aspx?flag=2&cmp_cd=114810&finGubun=MAIN&frq=0&sDT=20261014&chartType=image | X23: 27E 원표와 FnGuide 차이 10% 이내 또는 비교 자료 없음
A24: 유니셈 | B24: 036200 | C24: 3271 | D24: 372 | E24: 422 | F24: 8.8 | G24: 7.8 | I24: 8460 | J24: 30664223 | K24: 2026-10-15 정규장 종가 | L24: 사용자 첨부 IMG_7104~7108 / 원문 https://m.blog.naver.com/stockvera/224440085158 | M24: https://polling.finance.naver.com/api/realtime/domestic/stock/036200 | N24: https://polling.finance.naver.com/api/realtime/domestic/stock/036200 | O24: 0.1305 | P24: IFRS연결 | Q24: 2026-10-14 | R24: https://comp.wisereport.co.kr/company/ajax/c1050001_data.aspx?flag=2&cmp_cd=036200&finGubun=MAIN&frq=0&sDT=20261014&chartType=image | S24: 2027.12(E) ROE 직접 제공값과 대조 일치. 백분율 단위·종목코드 확인. | T24: 269 | U24: 280 | V24: IFRS연결 | W24: https://comp.wisereport.co.kr/company/ajax/c1050001_data.aspx?flag=2&cmp_cd=036200&finGubun=MAIN&frq=0&sDT=20261014&chartType=image | X24: 27E 원표와 FnGuide 차이 10% 이내 또는 비교 자료 없음
A25: 엘티씨 | B25: 170920 | C25: 4083 | D25: 464 | E25: 1174 | F25: 8.8 | G25: 3.5 | H25: † | I25: 30500 | J25: 10564126 | K25: 2026-10-15 정규장 종가 | L25: 사용자 첨부 IMG_7104~7108 / 원문 https://m.blog.naver.com/stockvera/224440085158 | M25: https://polling.finance.naver.com/api/realtime/domestic/stock/170920 | N25: https://polling.finance.naver.com/api/realtime/domestic/stock/170920 | O25: 0.2615 | P25: IFRS연결 | Q25: 2026-10-14 | R25: https://comp.wisereport.co.kr/company/ajax/c1050001_data.aspx?flag=2&cmp_cd=170920&finGubun=MAIN&frq=0&sDT=20261014&chartType=image | S25: 2027.12(E) ROE 직접 제공값과 대조 일치. 백분율 단위·종목코드 확인. | T25: 293 | U25: 733.5 | V25: IFRS연결 | W25: https://comp.wisereport.co.kr/company/ajax/c1050001_data.aspx?flag=2&cmp_cd=170920&finGubun=MAIN&frq=0&sDT=20261014&chartType=image | X25: 27E 원표와 FnGuide 차이 10% 이내 또는 비교 자료 없음
A26: 신성이엔지 | B26: 011930 | C26: 3773 | D26: 423 | E26: 276 | F26: 8.9 | G26: 13.7 | H26: † | I26: 15360 | J26: 20306182 | K26: 2026-10-15 정규장 종가 | L26: 사용자 첨부 IMG_7104~7108 / 원문 https://m.blog.naver.com/stockvera/224440085158 | M26: https://polling.finance.naver.com/api/realtime/domestic/stock/011930 | N26: https://polling.finance.naver.com/api/realtime/domestic/stock/011930 | O26: 미확인 | P26: IFRS연결 | Q26: 2026-10-14 | R26: https://comp.wisereport.co.kr/company/ajax/c1050001_data.aspx?flag=2&cmp_cd=011930&finGubun=MAIN&frq=0&sDT=20261014&chartType=image | S26: 2027년 이익 추정치는 있으나 2026/2027 BPS·ROE 미제공. 평균 예상 자기자본 미확인으로 계산 보류. 주재무·연결·별도 및 기업현황 화면 재조회. | T26: 388 | U26: 195 | V26: IFRS연결 | W26: https://comp.wisereport.co.kr/company/ajax/c1050001_data.aspx?flag=2&cmp_cd=011930&finGubun=MAIN&frq=0&sDT=20261014&chartType=image | X26: 27E 원표와 FnGuide 차이 10% 이내 또는 비교 자료 없음
A27: 해성디에스 | B27: 195870 | C27: 11000 | D27: 1164 | E27: 1498 | F27: 9.1 | G27: 7.1 | I27: 47700 | J27: 17000000 | K27: 2026-10-15 정규장 종가 | L27: 사용자 첨부 IMG_7104~7108 / 원문 https://m.blog.naver.com/stockvera/224440085158 | M27: https://polling.finance.naver.com/api/realtime/domestic/stock/195870 | N27: https://polling.finance.naver.com/api/realtime/domestic/stock/195870 | O27: 0.1687 | P27: IFRS연결 | Q27: 2026-10-14 | R27: https://comp.wisereport.co.kr/company/ajax/c1050001_data.aspx?flag=2&cmp_cd=195870&finGubun=MAIN&frq=0&sDT=20261014&chartType=image | S27: 2027.12(E) ROE 직접 제공값과 대조 일치. 백분율 단위·종목코드 확인. | T27: 812.3 | U27: 1025.5 | V27: IFRS연결 | W27: https://comp.wisereport.co.kr/company/ajax/c1050001_data.aspx?flag=2&cmp_cd=195870&finGubun=MAIN&frq=0&sDT=20261014&chartType=image | X27: 27E 원표와 FnGuide 차이 10% 이내 또는 비교 자료 없음
A28: 코세스 | B28: 089890 | C28: 5125 | D28: 540 | E28: 650 | F28: 9.5 | G28: 7.9 | I28: 26550 | J28: 16584962 | K28: 2026-10-15 정규장 종가 | L28: 사용자 첨부 IMG_7104~7108 / 원문 https://m.blog.naver.com/stockvera/224440085158 | M28: https://polling.finance.naver.com/api/realtime/domestic/stock/089890 | N28: https://polling.finance.naver.com/api/realtime/domestic/stock/089890 | O28: 0.4045 | P28: IFRS연결 | Q28: 2026-10-14 | R28: https://comp.wisereport.co.kr/company/ajax/c1050001_data.aspx?flag=2&cmp_cd=089890&finGubun=MAIN&frq=0&sDT=20261014&chartType=image | S28: 2027.12(E) ROE 직접 제공값과 대조 일치. 백분율 단위·종목코드 확인. | T28: 330 | U28: 390 | V28: IFRS연결 | W28: https://comp.wisereport.co.kr/company/ajax/c1050001_data.aspx?flag=2&cmp_cd=089890&finGubun=MAIN&frq=0&sDT=20261014&chartType=image | X28: 27E 원표와 FnGuide 차이 10% 이내 또는 비교 자료 없음
A29: LX세미콘 | B29: 108320 | C29: 5798 | D29: 610 | E29: 770 | F29: 9.5 | G29: 7.5 | I29: 31600 | J29: 16264300 | K29: 2026-10-15 정규장 종가 | L29: 사용자 첨부 IMG_7104~7108 / 원문 https://m.blog.naver.com/stockvera/224440085158 | M29: https://polling.finance.naver.com/api/realtime/domestic/stock/108320 | N29: https://polling.finance.naver.com/api/realtime/domestic/stock/108320 | O29: 0.0512 | P29: IFRS연결 | Q29: 2026-10-14 | R29: https://comp.wisereport.co.kr/company/ajax/c1050001_data.aspx?flag=2&cmp_cd=108320&finGubun=MAIN&frq=0&sDT=20261014&chartType=image | S29: 2027.12(E) ROE 직접 제공값과 대조 일치. 백분율 단위·종목코드 확인. | T29: 610 | U29: 781 | V29: IFRS연결 | W29: https://comp.wisereport.co.kr/company/ajax/c1050001_data.aspx?flag=2&cmp_cd=108320&finGubun=MAIN&frq=0&sDT=20261014&chartType=image | X29: 27E 원표와 FnGuide 차이 10% 이내 또는 비교 자료 없음
A30: 원익QnC | B30: 074600 | C30: 8517 | D30: 887 | E30: 1504 | F30: 9.6 | G30: 5.7 | H30: † | I30: 26250 | J30: 26288000 | K30: 2026-10-15 정규장 종가 | L30: 사용자 첨부 IMG_7104~7108 / 원문 https://m.blog.naver.com/stockvera/224440085158 | M30: https://polling.finance.naver.com/api/realtime/domestic/stock/074600 | N30: https://polling.finance.naver.com/api/realtime/domestic/stock/074600 | O30: 0.1467 | P30: IFRS연결 | Q30: 2026-10-14 | R30: https://comp.wisereport.co.kr/company/ajax/c1050001_data.aspx?flag=2&cmp_cd=074600&finGubun=MAIN&frq=0&sDT=20261014&chartType=image | S30: 2027.12(E) ROE 직접 제공값과 대조 일치. 백분율 단위·종목코드 확인. | T30: 716.67 | U30: 1166.33 | V30: IFRS연결 | W30: https://comp.wisereport.co.kr/company/ajax/c1050001_data.aspx?flag=2&cmp_cd=074600&finGubun=MAIN&frq=0&sDT=20261014&chartType=image | X30: 27E 원표와 FnGuide 차이 10% 이내 또는 비교 자료 없음
A31: 프로텍 | B31: 053610 | C31: 7056 | D31: 703 | E31: 800 | F31: 10 | G31: 8.8 | I31: 61600 | J31: 9000000 | K31: 2026-10-15 정규장 종가 | L31: 사용자 첨부 IMG_7104~7108 / 원문 https://m.blog.naver.com/stockvera/224440085158 | M31: https://polling.finance.naver.com/api/realtime/domestic/stock/053610 | N31: https://polling.finance.naver.com/api/realtime/domestic/stock/053610 | O31: 0.1537 | P31: IFRS연결 | Q31: 2026-10-14 | R31: https://comp.wisereport.co.kr/company/ajax/c1050001_data.aspx?flag=2&cmp_cd=053610&finGubun=MAIN&frq=0&sDT=20261014&chartType=image | S31: 2027.12(E) ROE 직접 제공값과 대조 일치. 백분율 단위·종목코드 확인. | T31: 787 | U31: 746 | V31: IFRS연결 | W31: https://comp.wisereport.co.kr/company/ajax/c1050001_data.aspx?flag=2&cmp_cd=053610&finGubun=MAIN&frq=0&sDT=20261014&chartType=image | X31: 27E 원표와 FnGuide 차이 10% 이내 또는 비교 자료 없음
A32: 저스템 | B32: 417840 | C32: 4493 | D32: 440 | E32: 516 | F32: 10.2 | G32: 8.7 | I32: 14870 | J32: 22946681 | K32: 2026-10-15 정규장 종가 | L32: 사용자 첨부 IMG_7104~7108 / 원문 https://m.blog.naver.com/stockvera/224440085158 | M32: https://polling.finance.naver.com/api/realtime/domestic/stock/417840 | N32: https://polling.finance.naver.com/api/realtime/domestic/stock/417840 | O32: 미확인 | P32: IFRS연결 | Q32: 2026-10-14 | R32: https://comp.wisereport.co.kr/company/ajax/c1050001_data.aspx?flag=2&cmp_cd=417840&finGubun=MAIN&frq=0&sDT=20261014&chartType=image | S32: 2027년 이익 추정치는 있으나 2026/2027 BPS·ROE 미제공. 평균 예상 자기자본 미확인으로 계산 보류. 주재무·연결·별도 및 기업현황 화면 재조회. | T32: 293.5 | U32: 345.74 | V32: IFRS연결 | W32: https://comp.wisereport.co.kr/company/ajax/c1050001_data.aspx?flag=2&cmp_cd=417840&finGubun=MAIN&frq=0&sDT=20261014&chartType=image | X32: 27E 원표와 FnGuide 차이 10% 이내 또는 비교 자료 없음
A33: 삼양엔씨켐 | B33: 482630 | C33: 3215 | D33: 300 | E33: 326 | F33: 10.7 | G33: 9.9 | I33: 12490 | J33: 21888280 | K33: 2026-10-15 정규장 종가 | L33: 사용자 첨부 IMG_7104~7108 / 원문 https://m.blog.naver.com/stockvera/224440085158 | M33: https://polling.finance.naver.com/api/realtime/domestic/stock/482630 | N33: https://polling.finance.naver.com/api/realtime/domestic/stock/482630 | O33: 0.1865 | P33: IFRS별도 | Q33: 2026-10-14 | R33: https://comp.wisereport.co.kr/company/ajax/c1050001_data.aspx?flag=2&cmp_cd=482630&finGubun=MAIN&frq=0&sDT=20261014&chartType=image | S33: 2027.12(E) ROE 직접 제공값과 대조 일치. 백분율 단위·종목코드 확인. | T33: 238.5 | U33: 242.5 | V33: IFRS별도 | W33: https://comp.wisereport.co.kr/company/ajax/c1050001_data.aspx?flag=2&cmp_cd=482630&finGubun=MAIN&frq=0&sDT=20261014&chartType=image | X33: 27E 원표와 FnGuide 차이 10% 이내 또는 비교 자료 없음
A34: 에이엘티 | B34: 172670 | C34: 1259 | D34: 116 | E34: 143 | F34: 10.9 | G34: 8.8 | I34: 11930 | J34: 8960259 | K34: 2026-10-15 정규장 종가 | L34: 사용자 첨부 IMG_7104~7108 / 원문 https://m.blog.naver.com/stockvera/224440085158 | M34: https://polling.finance.naver.com/api/realtime/domestic/stock/172670 | N34: https://polling.finance.naver.com/api/realtime/domestic/stock/172670 | O34: 미확인 | P34: IFRS연결 | Q34: 2026-10-14 | R34: https://comp.wisereport.co.kr/company/ajax/c1050001_data.aspx?flag=2&cmp_cd=172670&finGubun=MAIN&frq=0&sDT=20261014&chartType=image | S34: 2027년 이익 추정치는 있으나 2026/2027 BPS·ROE 미제공. 평균 예상 자기자본 미확인으로 계산 보류. 주재무·연결·별도 및 기업현황 화면 재조회. | T34: 28 | U34: 60 | V34: IFRS연결 | W34: https://comp.wisereport.co.kr/company/ajax/c1050001_data.aspx?flag=2&cmp_cd=172670&finGubun=MAIN&frq=0&sDT=20261014&chartType=image | X34: 27E 원표와 FnGuide 차이 10% 이내 또는 비교 자료 없음
A35: DB하이텍 | B35: 000990 | C35: 57000 | D35: 4930 | E35: 5525 | F35: 11.6 | G35: 10.4 | I35: 100000 | J35: 43504588 | K35: 2026-10-15 정규장 종가 | L35: 사용자 첨부 IMG_7104~7108 / 원문 https://m.blog.naver.com/stockvera/224440085158 | M35: https://polling.finance.naver.com/api/realtime/domestic/stock/000990 | N35: https://polling.finance.naver.com/api/realtime/domestic/stock/000990 | O35: 0.1789 | P35: IFRS연결 | Q35: 2026-10-14 | R35: https://comp.wisereport.co.kr/company/ajax/c1050001_data.aspx?flag=2&cmp_cd=000990&finGubun=MAIN&frq=0&sDT=20261014&chartType=image | S35: 2027.12(E) ROE 직접 제공값과 대조 일치. 백분율 단위·종목코드 확인. | T35: 4010 | U35: 4165 | V35: IFRS연결 | W35: https://comp.wisereport.co.kr/company/ajax/c1050001_data.aspx?flag=2&cmp_cd=000990&finGubun=MAIN&frq=0&sDT=20261014&chartType=image | X35: 27E 원표와 FnGuide 차이 10% 이내 또는 비교 자료 없음
A36: 뉴파워프라즈마 | B36: 144960 | C36: 6021 | D36: 495 | E36: 820 | F36: 12.2 | G36: 7.3 | H36: † | I36: 10440 | J36: 43692624 | K36: 2026-10-15 정규장 종가 | L36: 사용자 첨부 IMG_7104~7108 / 원문 https://m.blog.naver.com/stockvera/224440085158 | M36: https://polling.finance.naver.com/api/realtime/domestic/stock/144960 | N36: https://polling.finance.naver.com/api/realtime/domestic/stock/144960 | O36: 0.139 | P36: IFRS연결 | Q36: 2026-10-14 | R36: https://comp.wisereport.co.kr/company/ajax/c1050001_data.aspx?flag=2&cmp_cd=144960&finGubun=MAIN&frq=0&sDT=20261014&chartType=image | S36: 2027.12(E) ROE 직접 제공값과 대조 일치. 백분율 단위·종목코드 확인. | T36: 439 | U36: 691.67 | V36: IFRS연결 | W36: https://comp.wisereport.co.kr/company/ajax/c1050001_data.aspx?flag=2&cmp_cd=144960&finGubun=MAIN&frq=0&sDT=20261014&chartType=image | X36: 27E 원표와 FnGuide 차이 10% 이내 또는 비교 자료 없음
A37: 피엠티 | B37: 147760 | C37: 860 | D37: 70 | E37: 78 | F37: 12.3 | G37: 11 | I37: 3110 | J37: 20000000 | K37: 2026-10-15 정규장 종가 | L37: 사용자 첨부 IMG_7104~7108 / 원문 https://m.blog.naver.com/stockvera/224440085158 | M37: https://polling.finance.naver.com/api/realtime/domestic/stock/147760 | N37: https://polling.finance.naver.com/api/realtime/domestic/stock/147760 | O37: 미확인 | P37: IFRS별도 | Q37: 2026-10-14 | R37: https://comp.wisereport.co.kr/company/ajax/c1050001_data.aspx?flag=2&cmp_cd=147760&finGubun=MAIN&frq=0&sDT=20261014&chartType=image | S37: 2027년 이익 추정치는 있으나 2026/2027 BPS·ROE 미제공. 평균 예상 자기자본 미확인으로 계산 보류. 주재무·연결·별도 및 기업현황 화면 재조회. | T37: 11 | U37: 22 | V37: IFRS별도 | W37: https://comp.wisereport.co.kr/company/ajax/c1050001_data.aspx?flag=2&cmp_cd=147760&finGubun=MAIN&frq=0&sDT=20261014&chartType=image | X37: 27E 원표와 FnGuide 차이 10% 이내 또는 비교 자료 없음
A38: 하나마이크론 | B38: 067310 | C38: 32000 | D38: 2581 | E38: 4299 | F38: 12.5 | G38: 7.5 | H38: † | I38: 37100 | J38: 66490869 | K38: 2026-10-15 정규장 종가 | L38: 사용자 첨부 IMG_7104~7108 / 원문 https://m.blog.naver.com/stockvera/224440085158 | M38: https://polling.finance.naver.com/api/realtime/domestic/stock/067310 | N38: https://polling.finance.naver.com/api/realtime/domestic/stock/067310 | O38: 0.3238 | P38: IFRS연결 | Q38: 2026-10-14 | R38: https://comp.wisereport.co.kr/company/ajax/c1050001_data.aspx?flag=2&cmp_cd=067310&finGubun=MAIN&frq=0&sDT=20261014&chartType=image | S38: 2027.12(E) ROE 직접 제공값과 대조 일치. 백분율 단위·종목코드 확인. | T38: 2379.5 | U38: 4170.5 | V38: IFRS연결 | W38: https://comp.wisereport.co.kr/company/ajax/c1050001_data.aspx?flag=2&cmp_cd=067310&finGubun=MAIN&frq=0&sDT=20261014&chartType=image | X38: 27E 원표와 FnGuide 차이 10% 이내 또는 비교 자료 없음
A39: 하나머티리얼즈 | B39: 166090 | C39: 13000 | D39: 1008 | E39: 1316 | F39: 12.6 | G39: 9.6 | I39: 50300 | J39: 19777674 | K39: 2026-10-15 정규장 종가 | L39: 사용자 첨부 IMG_7104~7108 / 원문 https://m.blog.naver.com/stockvera/224440085158 | M39: https://polling.finance.naver.com/api/realtime/domestic/stock/166090 | N39: https://polling.finance.naver.com/api/realtime/domestic/stock/166090 | O39: 0.1514 | P39: IFRS연결 | Q39: 2026-10-14 | R39: https://comp.wisereport.co.kr/company/ajax/c1050001_data.aspx?flag=2&cmp_cd=166090&finGubun=MAIN&frq=0&sDT=20261014&chartType=image | S39: 2027.12(E) ROE 직접 제공값과 대조 일치. 백분율 단위·종목코드 확인. | T39: 736.5 | U39: 1000.2 | V39: IFRS연결 | W39: https://comp.wisereport.co.kr/company/ajax/c1050001_data.aspx?flag=2&cmp_cd=166090&finGubun=MAIN&frq=0&sDT=20261014&chartType=image | X39: 27E 원표와 FnGuide 차이 10% 이내 또는 비교 자료 없음
A40: 펨트론 | B40: 168360 | C40: 3323 | D40: 261 | E40: 336 | F40: 12.7 | G40: 9.9 | I40: 10530 | J40: 22392557 | K40: 2026-10-15 정규장 종가 | L40: 사용자 첨부 IMG_7104~7108 / 원문 https://m.blog.naver.com/stockvera/224440085158 | M40: https://polling.finance.naver.com/api/realtime/domestic/stock/168360 | N40: https://polling.finance.naver.com/api/realtime/domestic/stock/168360 | O40: 0.5073 | P40: IFRS연결 | Q40: 2026-10-14 | R40: https://comp.wisereport.co.kr/company/ajax/c1050001_data.aspx?flag=2&cmp_cd=168360&finGubun=MAIN&frq=0&sDT=20261014&chartType=image | S40: 2027.12(E) ROE 직접 제공값과 대조 일치. 백분율 단위·종목코드 확인. | T40: 146 | U40: 203 | V40: IFRS연결 | W40: https://comp.wisereport.co.kr/company/ajax/c1050001_data.aspx?flag=2&cmp_cd=168360&finGubun=MAIN&frq=0&sDT=20261014&chartType=image | X40: 27E 원표와 FnGuide 차이 10% 이내 또는 비교 자료 없음
A41: 와이씨켐 | B41: 112290 | C41: 2378 | D41: 186 | E41: 214 | F41: 12.8 | G41: 11.1 | I41: 9390 | J41: 20221090 | K41: 2026-10-15 정규장 종가 | L41: 사용자 첨부 IMG_7104~7108 / 원문 https://m.blog.naver.com/stockvera/224440085158 | M41: https://polling.finance.naver.com/api/realtime/domestic/stock/112290 | N41: https://polling.finance.naver.com/api/realtime/domestic/stock/112290 | O41: 0.3024 | P41: IFRS별도 | Q41: 2026-10-14 | R41: https://comp.wisereport.co.kr/company/ajax/c1050001_data.aspx?flag=2&cmp_cd=112290&finGubun=MAIN&frq=0&sDT=20261014&chartType=image | S41: 2027.12(E) ROE 직접 제공값과 대조 일치. 백분율 단위·종목코드 확인. | T41: 80 | U41: 95 | V41: IFRS별도 | W41: https://comp.wisereport.co.kr/company/ajax/c1050001_data.aspx?flag=2&cmp_cd=112290&finGubun=MAIN&frq=0&sDT=20261014&chartType=image | X41: 27E 원표와 FnGuide 차이 10% 이내 또는 비교 자료 없음
A42: 큐알티 | B42: 405100 | C42: 2047 | D42: 160 | E42: 215 | F42: 12.8 | G42: 9.5 | I42: 16630 | J42: 12289301 | K42: 2026-10-15 정규장 종가 | L42: 사용자 첨부 IMG_7104~7108 / 원문 https://m.blog.naver.com/stockvera/224440085158 | M42: https://polling.finance.naver.com/api/realtime/domestic/stock/405100 | N42: https://polling.finance.naver.com/api/realtime/domestic/stock/405100 | O42: 0.1624 | P42: IFRS연결 | Q42: 2026-10-14 | R42: https://comp.wisereport.co.kr/company/ajax/c1050001_data.aspx?flag=2&cmp_cd=405100&finGubun=MAIN&frq=0&sDT=20261014&chartType=image | S42: 2027.12(E) ROE 직접 제공값과 대조 일치. 백분율 단위·종목코드 확인. | T42: 90 | U42: 122 | V42: IFRS연결 | W42: https://comp.wisereport.co.kr/company/ajax/c1050001_data.aspx?flag=2&cmp_cd=405100&finGubun=MAIN&frq=0&sDT=20261014&chartType=image | X42: 27E 원표와 FnGuide 차이 10% 이내 또는 비교 자료 없음
A43: 오킨스전자 | B43: 080580 | C43: 5916 | D43: 456 | E43: 558 | F43: 13 | G43: 10.6 | I43: 23850 | J43: 21090955 | K43: 2026-10-15 정규장 종가 | L43: 사용자 첨부 IMG_7104~7108 / 원문 https://m.blog.naver.com/stockvera/224440085158 | M43: https://polling.finance.naver.com/api/realtime/domestic/stock/080580 | N43: https://polling.finance.naver.com/api/realtime/domestic/stock/080580 | O43: 0.4454 | P43: IFRS연결 | Q43: 2026-10-14 | R43: https://comp.wisereport.co.kr/company/ajax/c1050001_data.aspx?flag=2&cmp_cd=080580&finGubun=MAIN&frq=0&sDT=20261014&chartType=image | S43: 2027.12(E) ROE 직접 제공값과 대조 일치. 백분율 단위·종목코드 확인. | T43: 248 | U43: 296.5 | V43: IFRS연결 | W43: https://comp.wisereport.co.kr/company/ajax/c1050001_data.aspx?flag=2&cmp_cd=080580&finGubun=MAIN&frq=0&sDT=20261014&chartType=image | X43: 27E 원표와 FnGuide 차이 10% 이내 또는 비교 자료 없음
A44: GST | B44: 083450 | C44: 10000 | D44: 775 | E44: 946 | F44: 13.1 | G44: 10.8 | I44: 43600 | J44: 18430000 | K44: 2026-10-15 정규장 종가 | L44: 사용자 첨부 IMG_7104~7108 / 원문 https://m.blog.naver.com/stockvera/224440085158 | M44: https://polling.finance.naver.com/api/realtime/domestic/stock/083450 | N44: https://polling.finance.naver.com/api/realtime/domestic/stock/083450 | O44: 0.2019 | P44: IFRS연결 | Q44: 2026-10-14 | R44: https://comp.wisereport.co.kr/company/ajax/c1050001_data.aspx?flag=2&cmp_cd=083450&finGubun=MAIN&frq=0&sDT=20261014&chartType=image | S44: 2027.12(E) ROE 직접 제공값과 대조 일치. 백분율 단위·종목코드 확인. | T44: 627.33 | U44: 759 | V44: IFRS연결 | W44: https://comp.wisereport.co.kr/company/ajax/c1050001_data.aspx?flag=2&cmp_cd=083450&finGubun=MAIN&frq=0&sDT=20261014&chartType=image | X44: 27E 원표와 FnGuide 차이 10% 이내 또는 비교 자료 없음
...
